<?xml version='1.0' encoding='utf-8'?>
<robot xmlns:xacro="http://www.ros.org/wiki/xacro" name="panda_hand">

  <xacro:macro name="panda_hand" params="connected_to:='' arm_id:='' xyz:='0 0 0' rpy:='0 0 0' simulator:='none'">

    <xacro:include filename="$(find arclab_robot_description)/robots/manipulator/franka/utils.xacro"/>

    <xacro:unless value="${connected_to == ''}">
      <joint name="${arm_id}_hand_joint" type="fixed">
        <parent link="${connected_to}"/>
        <child link="${arm_id}_hand"/>
        <origin xyz="${xyz}" rpy="${rpy}"/>
      </joint>
    </xacro:unless>

    <link name="${arm_id}_hand">
      <visual>
        <geometry>
          <mesh filename="package://arclab_robot_description/meshes/manipulator/franka/visual/hand.dae"/>
        </geometry>
      </visual>
      <collision>
        <geometry>
          <mesh filename="package://arclab_robot_description/meshes/manipulator/franka/collision/hand.stl"/>
        </geometry>
      </collision>
      <inertial>
        <mass value="0.73"/>
        <origin xyz="-0.01 0 0.03"/>
        <inertia ixx="0.001" ixy="0" ixz="0"
                 iyy="0.0025" iyz="0"
                 izz="0.0017"/>
      </inertial>
    </link>

    <xacro:macro name="finger-collision" params="sign">
      <!-- screw mount -->
      <collision>
        <origin xyz="0 ${sign}18.5e-3 11e-3" rpy="0 0 0"/>
        <geometry>
          <box size="22e-3 15e-3 20e-3"/>
        </geometry>
      </collision>
      <!-- cartriage sledge -->
      <collision>
        <origin xyz="0 ${sign}6.8e-3 2.2e-3" rpy="0 0 0"/>
        <geometry>
          <box size="22e-3 8.8e-3 3.8e-3"/>
        </geometry>
      </collision>
      <!-- diagonal finger -->
      <collision>
        <origin xyz="0 ${sign}15.9e-3 28.35e-3" rpy="${sign}${pi/6} 0 0"/>
        <geometry>
          <box size="17.5e-3 7e-3 23.5e-3"/>
        </geometry>
      </collision>
      <!-- rubber tip with which to grasp -->
      <collision>
        <origin xyz="0 ${sign}7.58e-3 45.25e-3" rpy="0 0 0"/>
        <geometry>
          <box size="17.5e-3 15.2e-3 18.5e-3"/>
        </geometry>
      </collision>
    </xacro:macro>

    <xacro:unless value="${simulator == 'cartesio'}">

      <link name="${arm_id}_leftfinger">
        <xacro:inertia-cylinder mass="15e-3" radius="0.01" h="0.04"/>
        <visual>
          <geometry>
            <mesh filename="package://arclab_robot_description/meshes/manipulator/franka/visual/finger.dae"/>
          </geometry>
        </visual>
        <xacro:finger-collision sign="+"/>
      </link>

      <link name="${arm_id}_rightfinger">
        <xacro:inertia-cylinder mass="15e-3" radius="0.01" h="0.04"/>
        <visual>
          <origin xyz="0 0 0" rpy="0 0 ${pi}"/>
          <geometry>
            <mesh filename="package://arclab_robot_description/meshes/manipulator/franka/visual/finger.dae"/>
          </geometry>
        </visual>
        <xacro:finger-collision sign="-"/>
      </link>

      <joint name="${arm_id}_finger_joint1" type="prismatic">
        <parent link="${arm_id}_hand"/>
        <child link="${arm_id}_leftfinger"/>
        <origin xyz="0 0 0.0584" rpy="0 0 0"/>
        <axis xyz="0 1 0"/>
        <limit effort="100" lower="0.0" upper="0.04" velocity="0.2"/>
        <dynamics friction="0.0" damping="0.03"/>
      </joint>

      <xacro:unless value="${simulator == 'pinocchio'}">
        <joint name="${arm_id}_finger_joint2" type="prismatic">
          <parent link="${arm_id}_hand"/>
          <child link="${arm_id}_rightfinger"/>
          <origin xyz="0 0 0.0584" rpy="0 0 0"/>
          <axis xyz="0 -1 0"/>
          <limit effort="100" lower="0.0" upper="0.04" velocity="0.2"/>
          <dynamics friction="0.0" damping="0.03"/>
          <mimic joint="${arm_id}_finger_joint1"/>
        </joint>
      </xacro:unless>

      <xacro:if value="${simulator == 'pinocchio'}">
        <joint name="${arm_id}_finger_joint2" type="prismatic">
          <parent link="${arm_id}_hand"/>
          <child link="${arm_id}_rightfinger"/>
          <origin xyz="0 0 0.0584" rpy="0 0 0"/>
          <axis xyz="0 -1 0"/>
          <limit effort="100" lower="0.0" upper="0.04" velocity="0.2"/>
          <dynamics friction="0.0" damping="0.03"/>
        </joint>
      </xacro:if>

    </xacro:unless>

    <xacro:if value="${simulator == 'gazebo'}">
      <xacro:gazebo-friction link="${arm_id}_leftfinger" mu="1.13"/>
      <xacro:gazebo-friction link="${arm_id}_rightfinger" mu="1.13"/>

      <xacro:gazebo-joint joint="$(arg arm_id)_finger_joint1" transmission="hardware_interface/EffortJointInterface"/>
      <xacro:gazebo-joint joint="$(arg arm_id)_finger_joint2" transmission="hardware_interface/EffortJointInterface"/>
    </xacro:if>

  </xacro:macro>

</robot>
