<?xml version='1.0' encoding='utf-8'?>
<robot xmlns:xacro="http://www.ros.org/wiki/xacro" name="panda_arm">

  <!-- =============================================================== -->
  <!-- || This file does not contain official inertial properties   || -->
  <!-- || of panda robot. The values are from the identification    || -->
  <!-- || results published in: Identification of the Franka Emika  || -->
  <!-- || PandaRobot With Retrieval of Feasible Parameters Using    || -->
  <!-- || Penalty-Based Optimization                                || -->
  <!-- || by: Claudio Gaz, Marco Cognetti, Alexander Oliva,         || -->
  <!-- || Paolo Robuffo Giordano, Alessandro de Luca                || -->
  <!-- =============================================================== -->

  <xacro:macro name="panda_arm" params="arm_id:='panda' connected_to:='' xyz:='0 0 0' rpy:='0 0 0' simulator:='none'">

    <xacro:unless value="${not connected_to}">
      <joint name="${arm_id}_joint_${connected_to}" type="fixed">
        <parent link="${connected_to}"/>
        <child link="${arm_id}_link0"/>
        <origin rpy="${rpy}" xyz="${xyz}"/>
      </joint>
    </xacro:unless>

    <link name="${arm_id}_link0">
      <visual>
        <origin rpy="0 0 0" xyz="0 0 0"/>
        <geometry>
          <mesh filename="package://arclab_robot_description/meshes/manipulator/franka/visual/link0.dae"/>
        </geometry>
      </visual>
      <collision>
        <origin rpy="0 0 0" xyz="0 0 0"/>
        <geometry>
          <mesh filename="package://arclab_robot_description/meshes/manipulator/franka/collision/link0.stl"/>
        </geometry>
      </collision>
      <inertial>
        <!-- Estimated guesses from CAD -->
        <origin rpy="0 0 0" xyz="-0.041018 -0.00014 0.049974"/>
        <mass value="0.629769"/>
        <inertia ixx="0.00315" ixy="8.2904E-07" ixz="0.00015"
                               iyy="0.00388"    iyz="8.2299E-06"
                                                izz="0.004285" />
      </inertial>
    </link>

    <link name="${arm_id}_link1">
      <visual>
        <origin rpy="0 0 0" xyz="0 0 0"/>
        <geometry>
          <mesh filename="package://arclab_robot_description/meshes/manipulator/franka/visual/link1.dae"/>
        </geometry>
      </visual>
      <collision>
        <origin rpy="0 0 0" xyz="0 0 0"/>
        <geometry>
          <mesh filename="package://arclab_robot_description/meshes/manipulator/franka/collision/link1.stl"/>
        </geometry>
      </collision>
      <inertial>
        <origin rpy="0 0 0" xyz="0.003875 0.002081 -0.04762"/>
        <mass value="4.970684"/>
        <inertia ixx="0.70337" ixy="-0.00013900" ixz="0.0067720"
                               iyy="0.70661"     iyz="0.019169"
                                                 izz="0.0091170" />
      </inertial>
    </link>

    <joint name="${arm_id}_joint1" type="revolute">
      <safety_controller k_position="100.0" k_velocity="40.0" soft_lower_limit="-2.8973" soft_upper_limit="2.8973"/>
      <origin rpy="0 0 0" xyz="0 0 0.333"/>
      <parent link="${arm_id}_link0"/>
      <child link="${arm_id}_link1"/>
      <axis xyz="0 0 1"/>
      <limit acceleration="15" effort="87" lower="-2.8973" upper="2.8973" velocity="2.1750"/>
      <dynamics D="1" K="7000" mu_coulomb="0" mu_viscous="16" damping="0.003" friction="0.0"/>
    </joint>

    <link name="${arm_id}_link2">
      <visual>
        <origin rpy="0 0 0" xyz="0 0 0"/>
        <geometry>
          <mesh filename="package://arclab_robot_description/meshes/manipulator/franka/visual/link2.dae"/>
        </geometry>
      </visual>
      <collision>
        <origin rpy="0 0 0" xyz="0 0 0"/>
        <geometry>
          <mesh filename="package://arclab_robot_description/meshes/manipulator/franka/collision/link2.stl"/>
        </geometry>
      </collision>
      <inertial>
        <origin rpy="0 0 0" xyz=" -0.003141 -0.02872  0.003495"/>
        <mass value="0.646926"/>
        <inertia ixx="0.0079620" ixy="-3.9250e-3" ixz="1.0254e-02"
                                 iyy="2.8110e-02" iyz="7.0400e-04"
                                                  izz="2.5995e-02" />
      </inertial>
    </link>

    <joint name="${arm_id}_joint2" type="revolute">
      <safety_controller k_position="100.0" k_velocity="40.0" soft_lower_limit="-1.7628" soft_upper_limit="1.7628"/>
      <origin rpy="${-pi/2} 0 0" xyz="0 0 0"/>
      <parent link="${arm_id}_link1"/>
      <child link="${arm_id}_link2"/>
      <axis xyz="0 0 1"/>
      <limit acceleration="7.5" effort="87" lower="-1.7628" upper="1.7628" velocity="2.1750"/>
      <dynamics D="1" K="7000" mu_coulomb="0" mu_viscous="16" damping="0.003" friction="0.0"/>
    </joint>

    <link name="${arm_id}_link3">
      <visual>
        <origin rpy="0 0 0" xyz="0 0 0"/>
        <geometry>
          <mesh filename="package://arclab_robot_description/meshes/manipulator/franka/visual/link3.dae"/>
        </geometry>
      </visual>
      <collision>
        <origin rpy="0 0 0" xyz="0 0 0"/>
        <geometry>
          <mesh filename="package://arclab_robot_description/meshes/manipulator/franka/collision/link3.stl"/>
        </geometry>
      </collision>
      <inertial>
        <origin rpy="0 0 0" xyz="2.7518e-02 3.9252e-02 -6.6502e-02"/>
        <mass value="3.228604"/>
        <inertia ixx="3.7242e-02" ixy="-4.7610e-03" ixz="-1.1396e-02"
                                  iyy="3.6155e-02"  iyz="-1.2805e-02"
                                                    izz="1.0830e-02" />
      </inertial>
    </link>

    <joint name="${arm_id}_joint3" type="revolute">
      <safety_controller k_position="100.0" k_velocity="40.0" soft_lower_limit="-2.8973" soft_upper_limit="2.8973"/>
      <origin rpy="${pi/2} 0 0" xyz="0 -0.316 0"/>
      <parent link="${arm_id}_link2"/>
      <child link="${arm_id}_link3"/>
      <axis xyz="0 0 1"/>
      <limit acceleration="12.5" effort="87" lower="-2.8973" upper="2.8973" velocity="2.1750"/>
      <dynamics D="1" K="7000" mu_coulomb="0" mu_viscous="16" damping="0.003" friction="0.0"/>
    </joint>

    <link name="${arm_id}_link4">
      <visual>
        <origin rpy="0 0 0" xyz="0 0 0"/>
        <geometry>
          <mesh filename="package://arclab_robot_description/meshes/manipulator/franka/visual/link4.dae"/>
        </geometry>
      </visual>
      <collision>
        <origin rpy="0 0 0" xyz="0 0 0"/>
        <geometry>
          <mesh filename="package://arclab_robot_description/meshes/manipulator/franka/collision/link4.stl"/>
        </geometry>
      </collision>
      <inertial>
        <origin rpy="0 0 0" xyz="-5.317e-02 1.04419e-01 2.7454e-02"/>
        <mass value="3.587895"/>
        <inertia ixx="2.5853e-02" ixy="7.7960e-03" ixz="-1.3320e-03"
                                  iyy="1.9552e-02" iyz="8.6410e-03"
                                                   izz="2.8323e-02" />
      </inertial>
    </link>

    <joint name="${arm_id}_joint4" type="revolute">
      <safety_controller k_position="100.0" k_velocity="40.0" soft_lower_limit="-3.0718" soft_upper_limit="-0.0698"/>
      <origin rpy="${pi/2} 0 0" xyz="0.0825 0 0"/>
      <parent link="${arm_id}_link3"/>
      <child link="${arm_id}_link4"/>
      <axis xyz="0 0 1"/>
      <limit acceleration="12.5" effort="87" lower="-3.0718" upper="-0.0698" velocity="2.1750"/>
      <dynamics D="1" K="7000" mu_coulomb="0" mu_viscous="16" damping="0.003" friction="0.0"/>
    </joint>

    <link name="${arm_id}_link5">
      <visual>
        <origin rpy="0 0 0" xyz="0 0 0"/>
        <geometry>
          <mesh filename="package://arclab_robot_description/meshes/manipulator/franka/visual/link5.dae"/>
        </geometry>
      </visual>
      <collision>
        <origin rpy="0 0 0" xyz="0 0 0"/>
        <geometry>
          <mesh filename="package://arclab_robot_description/meshes/manipulator/franka/collision/link5.stl"/>
        </geometry>
      </collision>
      <inertial>
        <origin rpy="0 0 0" xyz="-1.1953e-02 4.1065e-02 -3.8437e-02"/>
        <mass value="1.225946"/>
        <inertia ixx="3.5549e-02" ixy="-2.1170e-03" ixz="-4.0370e-03"
                                  iyy="2.9474e-02"  iyz="2.2900e-04"
                                                    izz="8.6270e-03" />
      </inertial>
    </link>

    <joint name="${arm_id}_joint5" type="revolute">
      <safety_controller k_position="100.0" k_velocity="40.0" soft_lower_limit="-2.8973" soft_upper_limit="2.8973"/>
      <origin rpy="${-pi/2} 0 0" xyz="-0.0825 0.384 0"/>
      <parent link="${arm_id}_link4"/>
      <child link="${arm_id}_link5"/>
      <axis xyz="0 0 1"/>
      <limit acceleration="15" effort="12" lower="-2.8973" upper="2.8973" velocity="2.6100"/>
      <dynamics D="1" K="7000" mu_coulomb="0" mu_viscous="16" damping="0.003" friction="0.0"/>
    </joint>

    <link name="${arm_id}_link6">
      <visual>
        <origin rpy="0 0 0" xyz="0 0 0"/>
        <geometry>
          <mesh filename="package://arclab_robot_description/meshes/manipulator/franka/visual/link6.dae"/>
        </geometry>
      </visual>
      <collision>
        <origin rpy="0 0 0" xyz="0 0 0"/>
        <geometry>
          <mesh filename="package://arclab_robot_description/meshes/manipulator/franka/collision/link6.stl"/>
        </geometry>
      </collision>
      <inertial>
        <origin rpy="0 0 0" xyz="6.0149e-02 -1.4117e-02 -1.0517e-02"/>
        <mass value="1.666555"/>
        <inertia ixx="1.9640e-03" ixy="1.0900e-04" ixz="-1.1580e-03"
                                  iyy="4.3540e-03" iyz="3.4100e-04"
                                                   izz="5.4330e-03" />
      </inertial>
    </link>

    <joint name="${arm_id}_joint6" type="revolute">
      <safety_controller k_position="100.0" k_velocity="40.0" soft_lower_limit="-0.0175" soft_upper_limit="3.7525"/>
      <origin rpy="${pi/2} 0 0" xyz="0 0 0"/>
      <parent link="${arm_id}_link5"/>
      <child link="${arm_id}_link6"/>
      <axis xyz="0 0 1"/>
      <limit acceleration="20" effort="12" lower="-0.0175" upper="3.7525" velocity="2.6100"/>
      <dynamics D="1" K="7000" mu_coulomb="0" mu_viscous="16" damping="0.003" friction="0.0"/>
    </joint>

    <link name="${arm_id}_link7">
      <visual>
        <origin rpy="0 0 0" xyz="0 0 0"/>
        <geometry>
          <mesh filename="package://arclab_robot_description/meshes/manipulator/franka/visual/link7.dae"/>
        </geometry>
      </visual>
      <collision>
        <origin rpy="0 0 0" xyz="0 0 0"/>
        <geometry>
          <mesh filename="package://arclab_robot_description/meshes/manipulator/franka/collision/link7.stl"/>
        </geometry>
      </collision>
      <inertial>
        <origin rpy="0 0 0" xyz="1.0517e-02 -4.252e-03 6.1597e-02"/>
        <mass value="7.35522e-01"/>
        <inertia ixx="1.2516e-02" ixy="-4.2800e-04" ixz="-1.1960e-03"
                                  iyy="1.0027e-02"  iyz="-7.4100e-04"
                                                    izz="4.8150e-03"/>
      </inertial>
    </link>

    <joint name="${arm_id}_joint7" type="revolute">
      <safety_controller k_position="100.0" k_velocity="40.0" soft_lower_limit="-2.8973" soft_upper_limit="2.8973"/>
      <origin rpy="${pi/2} 0 0" xyz="0.088 0 0"/>
      <parent link="${arm_id}_link6"/>
      <child link="${arm_id}_link7"/>
      <axis xyz="0 0 1"/>
      <limit acceleration="20" effort="12" lower="-2.8973" upper="2.8973" velocity="2.6100"/>
      <dynamics D="1" K="7000" mu_coulomb="0" mu_viscous="16" damping="0.003" friction="0.0"/>
    </joint>

    <xacro:if value="${simulator == 'gazebo'}">
      <!-- Gazebo requires a joint to a link called "world" for statically mounted robots -->
      <xacro:if value="${not connected_to}">
        <link name="world"/>
        <joint name="world_joint" type="fixed">
          <origin xyz="${xyz}" rpy="${rpy}"/>
          <parent link="world"/>
          <child link="$(arg arm_id)_link0"/>
        </joint>
      </xacro:if>

      <xacro:include filename="$(find arclab_robot_description)/robots/manipulator/franka/utils.xacro"/>

      <xacro:gazebo-joint joint="$(arg arm_id)_joint1" transmission="hardware_interface/EffortJointInterface"/>
      <xacro:gazebo-joint joint="$(arg arm_id)_joint2" transmission="hardware_interface/EffortJointInterface"/>
      <xacro:gazebo-joint joint="$(arg arm_id)_joint3" transmission="hardware_interface/EffortJointInterface"/>
      <xacro:gazebo-joint joint="$(arg arm_id)_joint4" transmission="hardware_interface/EffortJointInterface"/>
      <xacro:gazebo-joint joint="$(arg arm_id)_joint5" transmission="hardware_interface/EffortJointInterface"/>
      <xacro:gazebo-joint joint="$(arg arm_id)_joint6" transmission="hardware_interface/EffortJointInterface"/>
      <xacro:gazebo-joint joint="$(arg arm_id)_joint7" transmission="hardware_interface/EffortJointInterface"/>

      <xacro:transmission-franka-state arm_id="$(arg arm_id)"/>
      <xacro:transmission-franka-model arm_id="$(arg arm_id)"
                                       root="$(arg arm_id)_joint1"
                                       tip="$(arg arm_id)_joint8"
      />

      <gazebo>
        <plugin name="gazebo_ros_control" filename="libgazebo_ros_control.so">
          <controlPeriod>0.001</controlPeriod>
          <robotSimType>franka_gazebo/FrankaHWSim</robotSimType>
        </plugin>
        <self_collide>true</self_collide>
      </gazebo>
    </xacro:if>

  </xacro:macro>

</robot>
